<mujoco model="two_link">
    <!--  Copyright © 2018, Roboti LLC

          This file is licensed under the MuJoCo Resource License (the "License").
          You may not use this file except in compliance with the License.
          You may obtain a copy of the License at

            https://www.roboti.us/resourcelicense.txt
    -->

    <include file="scene.xml"/>

    <option solver="CG" tolerance="1e-6"/>

    <size nconmax="50" njmax="500" nstack="50000"/>

    <worldbody>
      <body name="link1" pos="0 0 0.5">
          <geom type="box" size="0.05 0.05 0.05" rgba="0.15 0.5 0.15 1"/>
          <joint name="q1" type="hinge" pos="0 0 0" axis="0 0 1"/>
      </body>
    </worldbody>

    <actuator>
    		<motor name="motor_1" joint="q1" gear="1"/>
    </actuator>
</mujoco>
