<mujoco model="2-link 6-muscle arm">
    <!--  Copyright © 2018, Roboti LLC

          This file is licensed under the MuJoCo Resource License (the "License").
          You may not use this file except in compliance with the License.
          You may obtain a copy of the License at

            https://www.roboti.us/resourcelicense.txt
    -->

    <option timestep="0.005" iterations="50" solver="Newton" tolerance="1e-10"/>

    <size njmax="50" nconmax="10" nstack="200"/>

    <visual>
        <rgba haze=".3 .3 .3 1"/>
        <map znear="0.01" zfar="10"/>
    </visual>

    <default>
        <joint type="hinge" pos="0 0 0" axis="0 0 1" limited="true" range="0 120" damping="0.1"/>
        <muscle ctrllimited="true" ctrlrange="0 1"/>
    </default>

    <asset>
        <texture type="skybox" builtin="gradient" rgb1="0.6 0.6 0.6" rgb2="0 0 0" width="512" height="512"/>

        <texture name="texplane" type="2d" builtin="checker" rgb1="1 .25 .25" rgb2=".3 .3 .3" width="512" height="512" mark="cross" markrgb=".8 .8 .8"/>

        <material name="matplane" reflectance="0.3" texture="texplane" texrepeat="1 1" texuniform="true"/>
    </asset>

    <worldbody>
        <geom name="floor" pos="0 0 -0.5" size="0 0 1" type="plane" material="matplane"/>
        <geom fromto="0 0 0 0 0 -0.5" size=".5" type="cylinder"/>
        <light directional="true" diffuse=".8 .8 .8" specular=".2 .2 .2" pos="0 0 5" dir="0 0 -1"/>

        <body pos="0 0 0">
            <geom type="cylinder" size="0.1" fromto="0 0 0 0 0 0.2" rgba="0 0 0 1"/>
            <joint name="q1" type="hinge" axis="0 0 1" limited="true" range="-120 120"/>

            <camera name="camera-base" euler="90 -90 0" pos=".1 0 .08" fovy="90"/>

            <body pos="0 0 .2">
                <geom type="capsule" size="0.035" fromto="0 0 0  0.5 0 0" rgba=".5 .3 .1 1"/>
                <joint name="q2" type="hinge" axis="0 1 0" limited="true" range="-120 0"/>
                <body pos="0.5 0 0">
                    <geom type="capsule" size="0.035" fromto="0 0 0  0.5 0 0" rgba=".5 .3 .1 1"/>
                    <joint name="q3" type="hinge" axis="0 1 0" limited="true" range="0 120"/>

                    <camera name="camera-ee" euler="90 -90 0" pos=".5 0 0" fovy="90"/>
                </body>
            </body>
        </body>
    </worldbody>


    <actuator>
        <motor joint="q1" gear="1" ctrlrange="-20 20"/>
        <motor joint="q2" gear="1" ctrlrange="-20 20"/>
        <motor joint="q3" gear="1" ctrlrange="-20 20"/>
    </actuator>
</mujoco>
