<mujoco model="two_link">
    <!--  Copyright © 2018, Roboti LLC

          This file is licensed under the MuJoCo Resource License (the "License").
          You may not use this file except in compliance with the License.
          You may obtain a copy of the License at

            https://www.roboti.us/resourcelicense.txt
    -->

    <include file="scene.xml"/>

    <option solver="CG" tolerance="1e-6"/>

    <size nconmax="50" njmax="500" nstack="50000"/>

    <worldbody>
      <body name="link1" pos="0 0 0.5">
          <geom type="capsule" fromto="0 0 0 0.25 0 0" size="0.05" rgba="0.15 0.5 0.15 1"/>
          <joint name="q1" type="hinge" pos="0 0 0" axis="0 0 1" limited="true" range="-120 120"/>
              <body name="link2" pos="0.25 0 0">
                  <geom type="capsule" fromto="0 0 0 0.25 0 0" size="0.035" rgba="0.5 0.15 0.15 1"/>
                  <joint name="q2" type="hinge" pos="0 0 0" axis="0 0 1" limited="true" range="-120 120"/>
                  <site name="ee" rgba="0 0 0 1" pos="0.25 0 0"/>
                  <site name="ee_visual" rgba="0 0 0 1" pos="0.25 0 0.035"/>
              </body>
      </body>
    </worldbody>

    <actuator>
    		<motor name="motor_1" joint="q1" gear="1"/>
    		<motor name="motor_2" joint="q2" gear="1"/>
    </actuator>
</mujoco>
